Workbook

Sheet TOTAL BUDGET
B2: FULL PRODUCTION COST
C4: Materials | D4: =MATERIALS!D20 -> 200985
C7: Estimated development sprints | D7: 5
C8: Price/sprint | D8: ='DEVELOPMENT SPRINT BUDGET'!J18 -> 196000
D10: Total days | E10: €/hour | F10: Price
C11: Project Manager | D11: =SUM('DEVELOPMENT SPRINT BUDGET'!D5:D16)*'TOTAL BUDGET'!D7 -> 1460 | E11: 25 | F11: =D11*E11*7 -> 255500
D14: =MATERIALS!D6+D7*D8+F11 -> 1242485
C15: Contingency (25%) | D15: =0.25*D14 -> 310621.25
C16: Total | D16: =SUM(D14:D15) -> 1553106.2

Sheet DEVELOPMENT SPRINT BUDGET
B3: DEVELOPMENT sprint
D4: Days | E4: Total hours | F4: Senior (€/hour) | G4: Quantity senior | H4: Junior (€/hour) | I4: Quantity Junior | J4: Total price €
C5: Game Design | D5: 35 | E5: =D5*7 -> 245 | F5: 30 | G5: 3 | H5: 15 | I5: 2 | J5: =E5*(F5*G5+H5*I5) -> 29400
B6: DESIGN | C6: Character design | D6: 15 | E6: =D6*7 -> 105 | F6: 30 | G6: 2 | H6: 15 | I6: 0 | J6: =E6*(F6*G6+H6*I6) -> 6300
C7: Concept art | D7: 15 | E7: =D7*7 -> 105 | F7: 30 | G7: 2 | H7: 15 | I7: 1 | J7: =E7*(F7*G7+H7*I7) -> 7875
C9: Animation | D9: =ROUNDUP('ANIMATION Est.TIME'!J43/7,0) -> 91 | E9: =D9*7 -> 637 | F9: 30 | G9: 2 | H9: 15 | I9: 1 | J9: =E9*(F9*G9+H9*I9) -> 47775
B10: DEVELOPMENT | C10: Programming | D10: ='PROGRAMMING TOTAL Est. TIME'!E12 -> 78 | E10: =D10*7 -> 546 | F10: 26 | G10: 3 | H10: 15 | I10: 5 | J10: =E10*(F10*G10+H10*I10) -> 83538
C11: Environment | D11: ='ENVIRONMENT Est TIME'!F12 -> 46 | E11: =D11*7 -> 322 | F11: 20 | G11: 2 | H11: 15 | I11: 1 | J11: =E11*(F11*G11+H11*I11) -> 17710
C12: Sound design | D12: 3 | E12: =D12*7 -> 21 | F12: 20 | G12: 1 | H12: 15 | I12: 1 | J12: =E12*(F12*G12+H12*I12) -> 735
C14: Target audience | D14: 5 | E14: =D14*7 -> 35 | F14: 15 | G14: 2 | H14: 9 | I14: 1 | J14: =E14*(F14*G14+H14*I14) -> 1365
B15: TESTING | C15: New Players | D15: 2 | E15: =D15*7 -> 14 | F15: 15 | G15: 3 | H15: 9 | I15: 1 | J15: =E15*(F15*G15+H15*I15) -> 756
C16: Expert players | D16: 2 | E16: =D16*7 -> 14 | F16: 15 | G16: 2 | H16: 9 | I16: 1 | J16: =E16*(F16*G16+H16*I16) -> 546
B18: Total | J18: =SUM(J5:J16) -> 196000
E23: *NOTE: We have estimated a studio with
E24: one senior game designer,
E25: character designer,
E26: concept artist,
E27: animator,
E28: programmer and
E29: 3D generalist (environment).
E31: 6 testers and one sound designer.
E32: Consider to modify it if needed

Sheet MATERIALS
B3: Materials
C5: Uses mocap? (Y/N) | D5: Budget
C6: =IF('ANIMATION Est.TIME'!$I$35>0,"Y","N") -> Y | D6: =IF(C6="Y",SUM('ANIMATION Est.TIME'!D30:F30),0) -> 6985
D9: Quantity | E9: Price | F9: Total
C10: Consolas y mandos | D10: ='DEVELOPMENT SPRINT BUDGET'!G5+'DEVELOPMENT SPRINT BUDGET'!G6+'DEVELOPMENT SPRINT BUDGET'!G7+'DEVELOPMENT SPRINT BUDGET'!G9+'DEVELOPMENT SPRINT BUDGET'!G11 -> 11 | E10: 1000 | F10: =D10*E10 -> 11000
C11: PC Alto Rendimiento | D11: ='DEVELOPMENT SPRINT BUDGET'!G5+'DEVELOPMENT SPRINT BUDGET'!G10+'DEVELOPMENT SPRINT BUDGET'!G11+'DEVELOPMENT SPRINT BUDGET'!G9 -> 10 | E11: 4000 | F11: =D11*E11 -> 40000
C12: PC Normal | D12: ='DEVELOPMENT SPRINT BUDGET'!G6+'DEVELOPMENT SPRINT BUDGET'!G7+'DEVELOPMENT SPRINT BUDGET'!G12+'DEVELOPMENT SPRINT BUDGET'!G14+'DEVELOPMENT SPRINT BUDGET'!G15+'DEVELOPMENT SPRINT BUDGET'!G16 -> 12 | E12: 1500 | F12: =D12*E12 -> 18000
E14: Months | F14: Total
C15: Office rent (month) | D15: 2500 | E15: =ROUNDUP('TOTAL BUDGET'!D11/30,0) -> 49 | F15: =D15*E15 -> 122500
C17: Total materials | D17: =SUM(D6,F10,F11,F12,D15) -> 78485
C18: Amortisation (4 years) | D18: =ROUND(D17/(4*365)*'TOTAL BUDGET'!D11,2) -> 78485
C20: Total mat. Amort+off. | D20: =D18+F15 -> 200985

Sheet PROGRAMMING TOTAL Est. TIME
C2: PROGRAMMING TOTALS
E4: Days
D5: PROGRAMING MECHANICS | E5: ='PROGRAMMING MECHANIC Est. TIME'!C532 -> 32
D6: SCRIPTING LEVELS | E6: =E21 -> 11
D7: OPTIMIZATION (LODs, WORLD PARTITION) | E7: 20
D8: MULTIPLAYER MODE | E8: 0
D9: SAVING DATA SYSTEM | E9: 3
D10: GUI | E10: 7
D11: BUILD | E11: 5
D12: TOTAL | E12: =SUM(E5:E11) -> 78
D17: Scipting levels
D18: Number of levels | E18: 10
D19: Number of Game rules/styles per loop | E19: 3
D20: Average complexity (1-10) | E20: 6
D21: Days | E21: =ROUNDUP(E19*(E20*3/10)+(E18/2),0) -> 11

Sheet PROGRAMMING MECHANIC Est. TIME
B3: Game Mechanic #1
B5: Name: | C5: Nivel de Corrupción
B8: Description: | C8: Sustituye la barra de vida tradicional. Cada acción política o interacción con enemigos incrementa el nivel de corrupción. Si llega al 100%, el jugador pierde. Se integra con todas las mecánicas del juego, afectando decisiones estratégicas y generando tensión constante.
B14: References: | C14: Darkest Dungeon (estrés).
B15: (other videogames where it appears) | C15: Resident Evil (sistema de infección).
B18: Technical complexity (1-10) | C18: 6
B21: Resource_interaction (1-10) | C21: 5
B22: Level of interaction with artistic resources/
B23: external data/other game objects
B26: Testing and debugging (1-10) | C26: 6
B27: Technical effort on testing and debugging
B30: Performance impact (1-10) | C30: 4
B32: Scalability (1-10) | C32: 5
B33: Difficulty on scaling this mechanic
B35: Innovation (1-10) | C35: 9
B37: Team experience (1-10) | C37: 6
B38: Experience on this type of mechanics
B40: EXPERIENCE FACTOR (auto-calculated) | C40: =1-(C37/20) -> 0.7
B43: TOTAL TIME (DAYS) (auto-calculated) | C43: =ROUNDUP((0.3*C18+0.2*C21+0.2*C26+0.15*C30+0.1*C32+0.05*C35)*C40,0) -> 4
B47: Game Mechanic #2
B49: Name: | C49: Afinidades Políticas (Piedra-Papel-Tijera)
B52: Description: | C52: Sistema RPG que define ventajas y desventajas en combate según ideología: Liberal > Conservador > Socialista. Influye en daño, defensa y reclutamiento. Se aplica tanto a enemigos como a aliados.
B58: References: | C58: Pokemon (Sistema de Tipos)
B59: (other videogames where it appears) | C59: Fire Emblem (triángulo de armas).
C60: Monster Hunter Stories (Sistema de Tipos)
B62: Technical complexity (1-10) | C62: 4
B65: Resource_interaction (1-10) | C65: 4
B66: Level of interaction with artistic resources/
B67: external data/other game objects
B70: Testing and debugging (1-10) | C70: 5
B71: Technical effort on testing and debugging
B74: Performance impact (1-10) | C74: 3
B76: Scalability (1-10) | C76: 5
B77: Difficulty on scaling this mechanic
B79: Innovation (1-10) | C79: 6
B81: Team experience (1-10) | C81: 6
B82: Experience on this type of mechanics
B84: EXPERIENCE FACTOR (auto-calculated) | C84: =1-(C81/20) -> 0.7
B87: TOTAL TIME (DAYS) (auto-calculated) | C87: =ROUNDUP((0.3*C62+0.2*C65+0.2*C70+0.15*C74+0.1*C76+0.05*C79)*C84,0) -> 3
B91: Game Mechanic #3
...

Sheet ANIMATION Est.TIME
B2: Link Trello
B5: 2D animation | C5: Character/asset | D5: Main (Y/N) | E5: Nº animations | F5: Layouts (hours/anim) | G5: Draft animation (hours/anim) | H5: Clean up (hours/anim) | I5: Total hours
C6: Pedro Sánchez | D6: Y | E6: 10 | F6: 2 | G6: 4 | H6: 3 | I6: =E6*(F6+G6+H6) -> 90
C7: Donald Trump | D7: N | E7: 4 | F7: 2 | G7: 3 | H7: 2 | I7: =E7*(F7+G7+H7) -> 28
C8: Xi Jinping | D8: N | E8: 4 | F8: 2 | G8: 3 | H8: 2 | I8: =E8*(F8+G8+H8) -> 28
C9: Mazón | D9: N | E9: 4 | F9: 2 | G9: 3 | H9: 2 | I9: =E9*(F9+G9+H9) -> 28
C10: Feijo | D10: N | E10: 4 | F10: 2 | G10: 3 | H10: 2 | I10: =E10*(F10+G10+H10) -> 28
C11: Pablo Iglesias | D11: N | E11: 4 | F11: 2 | G11: 3 | H11: 2 | I11: =E11*(F11+G11+H11) -> 28
C12: Abascal | D12: N | E12: 4 | F12: 2 | G12: 3 | H12: 2 | I12: =E12*(F12+G12+H12) -> 28
C13: Ayuso | D13: N | E13: 4 | F13: 2 | G13: 3 | H13: 2 | I13: =E13*(F13+G13+H13) -> 28
C14: Macron | D14: N | E14: 4 | F14: 2 | G14: 3 | H14: 2 | I14: =E14*(F14+G14+H14) -> 28
C15: Angela Merkle | D15: N | E15: 4 | F15: 2 | G15: 3 | H15: 2 | I15: =E15*(F15+G15+H15) -> 28
C16: Kim Jon Ung | D16: N | E16: 4 | F16: 2 | G16: 3 | H16: 2 | I16: =E16*(F16+G16+H16) -> 28
C17: Joe Biden | D17: N | E17: 4 | F17: 2 | G17: 3 | H17: 2 | I17: =E17*(F17+G17+H17) -> 28
C18: Echenque | D18: N | E18: 4 | F18: 2 | G18: 3 | H18: 2 | I18: =E18*(F18+G18+H18) -> 28
I19: =SUM(I6:I18) -> 426
B23: 3D animation | C23: Character | D23: Asset (Y/N) | E23: Nº animations | F23: Modelling (hours/model) | G23: Texturing (hours/model) | H23: Rigging (hours/char) | I23: Animation (hours/anim) | J23: Total hours
C24: Pedro Sánchez | D24: N | E24: 6 | F24: 20 | G24: 4 | H24: 10 | I24: 8 | J24: =IF(D24="N",F24+G24+H24+(I24*E24),(I24*E24)+F24+G24) -> 82
C25: Donald Trump | D25: N | E25: 3 | F25: 10 | G25: 5 | H25: 10 | I25: 8 | J25: =IF(D25="N",F25+G25+H25+(I25*E25),(I25*E25)+F25+G25) -> 49
C26: Tribunal de Cuenats | D26: N | E26: 2 | F26: 15 | G26: 7 | H26: 10 | I26: 8 | J26: =IF(D26="N",F26+G26+H26+(I26*E26),(I26*E26)+F26+G26) -> 48
J27: =SUM(J24:J26) -> 179
D29: Pro-Coil | E29: Smartsuit Pro | F29: SmartGloves
B30: Mocap | C30: Initial investment | D30: 2995 | E30: 2245 | F30: 1745
C31: Character | D31: Nº animations | E31: Modelling (hours/model) | F31: Texturing (hours/model) | G31: Rigging (hours/char) | H31: Animation (hours/anim) | I31: Total hours
C32: Pedro Sánchez | D32: 10 | E32: 20 | F32: 5 | G32: 2 | H32: 0.1 | I32: =E32+F32+G32+(H32*D32) -> 28
I33: =E33+F33+G33+(H33*D33) -> 0
I34: =E34+F34+G34+(H34*D34) -> 0
I35: =SUM(I32:I34) -> 28
J42: TOTAL hours
J43: =SUM(I35,J27,I19) -> 633
B48: Add any row you need

Sheet ENVIRONMENT Est TIME
D3: Nº Props | E3: Hours modelling/texturing /prop | F3: Hours props
D4: 10 | E4: 12 | F4: =E4*D4 -> 120
C7: Nº levels | E7: Environment composition, effects, light and limits (hours) | F7: Hours composition
C8: 10 | E8: 20 | F8: =C8*E8 -> 200
E10: Previously 4 and 5 hours, increased heavily as we want photorealistic scenarios
F11: Total days
F12: =ROUNDUP((F8+F4)/7,0) -> 46
